Workbook

Sheet Summary
A1: RIIPEN CAREER CATALYST
A2: Weekly Time Allocation — Summary
A4: Week | B4: Title | C4: Total (min) | D4: Total (hrs) | E4: Cumulative (hrs) | F4: Gap to 135 hrs
A5: 1 | B5: Getting Started | C5: =Detail!F18 | D5: =C5/60 | E5: =D5 | F5: =135-E5
A6: 2 | B6: Building Your Team | C6: =Detail!F35 | D6: =C6/60 | E6: =E5+D6 | F6: =135-E6
A7: 3 | B7: Understanding Your Client | C7: =Detail!F41 | D7: =C7/60 | E7: =E6+D7 | F7: =135-E7
A8: 4 | B8: From Research to Strategy | C8: =Detail!F47 | D8: =C8/60 | E8: =E7+D8 | F8: =135-E8
A9: 5 | B9: Professional Communication | C9: =Detail!F53 | D9: =C9/60 | E9: =E8+D9 | F9: =135-E9
A10: 6 | B10: Working Through Ambiguity | C10: =Detail!F59 | D10: =C10/60 | E10: =E9+D10 | F10: =135-E10
A11: 7 | B11: Progress Review | C11: =Detail!F65 | D11: =C11/60 | E11: =E10+D11 | F11: =135-E11
A12: 8 | B12: Making Feedback Useful | C12: =Detail!F71 | D12: =C12/60 | E12: =E11+D12 | F12: =135-E12
A13: 9 | B13: Teamwork Under Pressure | C13: =Detail!F77 | D13: =C13/60 | E13: =E12+D13 | F13: =135-E13
A14: 10 | B14: Connecting Theory & Practice | C14: =Detail!F83 | D14: =C14/60 | E14: =E13+D14 | F14: =135-E14
A15: 11 | B15: Quality and Craft | C15: =Detail!F89 | D15: =C15/60 | E15: =E14+D15 | F15: =135-E15
A16: 12 | B16: From Feedback to Final | C16: =Detail!F95 | D16: =C16/60 | E16: =E15+D16 | F16: =135-E16
A17: 13 | B17: Finalizing Deliverables | C17: =Detail!F101 | D17: =C17/60 | E17: =E16+D17 | F17: =135-E17
A18: 14 | B18: Presenting Your Work | C18: =Detail!F107 | D18: =C18/60 | E18: =E17+D18 | F18: =135-E18
A19: 15 | B19: Transfer and What's Next | C19: =Detail!F113 | D19: =C19/60 | E19: =E18+D19 | F19: =135-E19
A20: TOTAL | C20: =SUM(C5:C19) | D20: =SUM(D5:D19) | E20: 135 target | F20: =135-D20

Sheet Detail
A1: RIIPEN CAREER CATALYST — Weekly Activity Breakdown (All Weeks)
A2: Week | B2: Phase | C2: Activity | D2: Category | E2: Format | F2: Time (min) | G2: Note
A3: WEEK 1 — GETTING STARTED | Foundation
A4: 1.01 | B4: Course Orientation | C4: Welcome to Career Catalyst Week 1 | D4: Module | E4: Text | F4: 5 | G4: Provides an overview of what will be covered this week, objectives, suggested order of completion and time estimates.
A5: 1.02 | B5: Course Orientation | C5: What Is Experiential Learning? | D5: Module | F5: 15 | G5: Frames the learning cycle and sets expectations for how this course differs from traditional coursework
A6: 1.03 | B6: Course Orientation | C6: Syllabus and assessment review | D6: Admin | F6: 30 | G6: Foundational for academic integrity and student planning. Students look ahead to what is expected and how they will be assessed in the course.
A7: 1.04 | B7: Course Orientation | C7: AI in the Today's Workplace & This Course | D7: Module | F7: 30 | G7: Introduces the AI-enabled workplace context and ties it to the course's policy orientation: what's permitted, what requires disclosure, the defend-your-work standard
A8: 1.05 | B8: Course Orientation | C8: Your Project and Team | D8: Module | F8: 30 | G8: Orients students to the project-based structure and how they will be expected to work in teams
A9: 1.06 | B9: Course Orientation | C9: Platform orientation | D9: Admin | F9: 15 | G9: Navigating Riipen and LMS; reduces friction in subsequent weeks
A10: 1.07 | B10: Project Work | C10: Review project briefs | D10: Project | F10: 60 | G10: Students browse all available briefs before deep-reading; skimming first prevents anchoring on the first brief encountered; students select finalists based on initial skim and read carefully before forming a preference
A11: 1.08 | B11: Project Work | C11: Complete student intake, including preference submission with written rationale | D11: Project | F11: 45 | G11: Frames the purpose of the intake questionnaire, how it will support project matching, and should be used for reflection and goal-tracking. Written justification for project selections required; develops reasoned decision-making and surfaces student priorities.
A12: 1.09 | B12: Course Orientation | C12: LMS introduction post + reading peers | D12: Admin | F12: 60 | G12: Community-building before teams are assigned; students post a self-intro and respond to peers
A13: 1.1 | B13: Professional Fundamentals | C13: Setting Yourself Up for Success | D13: Module | F13: 30 | G13: Time management and planning basics for project-based work; early semester planning is a reliable predictor of student performance
A14: 1.11 | B14: Course Orientation | C14: Course calendar / planning | D14: Admin | F14: 15 | G14: Students map deliverable dates to their own calendars; supports time management and reduces late submissions
A15: 1.12 | B15: Professional Fundamentals | C15: Professional Email Basics | D15: Module | F15: 30 | G15: Practical skill introduced before students need to communicate professionally; applies immediately in Week 2 outreach
A16: 1.13 | B16: Project Work | C16: Team norms overview | D16: Project | F16: 30 | G16: Pre-exposure to Week 2 content before teams are assigned; students arrive primed for the charter conversation
A17: 1.14 | B17: Project Work | C17: Team Charter template review | D17: Project | F17: 15 | G17: Template review only — not completed this week; reduces cognitive load when teams meet in Week 2
A18: Week Total | F18: =SUM(F4:F17) | G18: =F18/60
A20: WEEK 2 — BUILDING YOUR TEAM | Foundation
A21: 2.01 | B21: Team Formation | C21: Building Your Team module section | D21: Module | F21: 20 | G21: Covers team dynamics, charter negotiation, and establishing norms; delivered before the first team meeting so students arrive with a shared frame for the charter conversation
A22: 2.02 | B22: Team Formation | C22: First contact with teammates + scheduling | D22: Project | F22: 20 | G22: Initiating contact, finding a meeting time across four schedules; inherently inefficient for strangers; async coordination via email or LMS messaging
A23: 2.03 | B23: Team Formation | C23: First team meeting | D23: Project | F23: 90 | G23: 90-minute synchronous meeting covering introductions, shared read-through of the project brief, initial reactions, and charter negotiation; 75 min was too lean for strangers tackling a real deliverable together for the first time
A24: 2.04 | B24: Team Formation | C24: Team Charter drafting, review, and finalization | D24: Project | F24: 60 | G24: One team member drafts after the meeting; async back-and-forth to finalize; all four students must agree on the substance before the charter is complete
A25: 2.05 | B25: Team Formation | C25: Async team communication across the week | D25: Project | F25: 15 | G25: Coordination outside of the meeting; Slack, email, or LMS; lighter than subsequent weeks because the relationship is brand new and norms are still forming
A26: 2.06 | B26: Employer Engagement | C26: First Client Communication module section | D26: Module | F26: 20 | G26: Professional email, scheduling logistics, representing the team; delivered before students draft the outreach email so the skill is introduced immediately before application
A27: 2.07 | B27: Employer Engagement | C27: Draft and agree on employer outreach email | D27: Project | F27: 35 | G27: Team drafts the introduction email and requests the kickoff meeting; collective agreement required before sending; AI-assisted drafting is permitted with disclosure
A28: 2.08 | B28: Employer Engagement | C28: Employer scheduling coordination | D28: Project | F28: 15 | G28: Follow-up to confirm receipt and handle logistics; brief but real; missing from original time estimate
A29: 2.09 | B29: Project Orientation | C29: Kickoff Preparation module section | D29: Module | F29: 20 | G29: What to research, how to prepare questions, what to listen for at the kickoff; just-in-time for the meeting happening in Week 3
A30: 2.1 | B30: Project Orientation | C30: Using AI Responsibly module section | D30: Module | F30: 35 | G30: How to prompt well, how to evaluate AI output critically, how to verify claims, how to use AI as a thinking partner rather than an answer machine; includes example prompts and critical evaluation exercises; first formal introduction of prompt strategy
A31: 2.11 | B31: Project Orientation | C31: Individual research on employer organization | D31: Project | F31: 50 | G31: Students now have a real project assignment and genuine motivation to understand Maple & Main; website, social media, news coverage, sector context; feeds Context Analysis in Week 4
A32: 2.12 | B32: Project Orientation | C32: Review Context Analysis & Project Plan assignment + rubric | D32: Project | F32: 25 | G32: Better timing than Week 1 — students now have a real project to contextualize the rubric against; knowing the assessment criteria before beginning work shapes what they prioritize in research and charter conversations
... A34: 2.14 | B34: Admin | C34: Review teammates’ LMS intro posts | D34: Admin | F34: 15 | G34: Now that team assignments are known, students read their teammates’ Week 1 intro posts; community-building with the specific people they’ll be working with for 15 weeks
A35: Week Total | F35: =SUM(F21:F34) | G35: =F35/60
A37: WEEK 3 — UNDERSTANDING YOUR CLIENT | Foundation
C39: [Activity to be added]
A41: Week Total | F41: =SUM(F38:F40) | G41: =F41/60
A43: WEEK 4 — FROM RESEARCH TO STRATEGY | Discovery
C45: [Activity to be added]
A47: Week Total | F47: =SUM(F44:F46) | G47: =F47/60
A49: WEEK 5 — PROFESSIONAL COMMUNICATION | Discovery
...
